<?xml version="1.0"?>
<robot name="lebai_lm3">

  <link name="world">
  </link>

  <link name="base_link">
    <visual>
      <origin xyz="0 0 0" rpy="0 0 0" />
      <geometry>
        <mesh filename="meshes/lm3/visual/base_link.stl" />
      </geometry>
      <material name="base_link_mat">
        <color rgba="0.85882745 0.84706275 0.80784706 1.00000000"/>
      </material>
    </visual>
    <collision>
      <origin xyz="0 0 0" rpy="0 0 0" />
      <geometry>
        <mesh filename="meshes/lm3/collision/base_link.stl" />
      </geometry>
    </collision>
  </link>

  <link name="link_1">
    <visual>
      <origin xyz="0 0 0" rpy="0 0 0" />
      <geometry>
        <mesh filename="meshes/lm3/visual/link1.stl" />
      </geometry>
      <material name="link_1_mat">
        <color rgba="0.85882745 0.84706275 0.80784706 1.00000000"/>
      </material>
    </visual>
    <collision>
      <origin xyz="0 0 0" rpy="0 0 0" />
      <geometry>
        <mesh filename="meshes/lm3/collision/link1.stl" />
      </geometry>
    </collision>
    <inertial>
      <origin xyz="0 -0.011 -0.015" rpy="0 0 0" />
      <mass value="2.147" />
      <inertia ixx="0.0082391" ixy="0" ixz="0" iyy="0.0076088" iyz="0.0003238" izz="0.0032574" />
    </inertial>
  </link>

  <link name="link_2">
    <visual>
      <origin xyz="0 0 0" rpy="0 0 0" />
      <geometry>
        <mesh filename="meshes/lm3/visual/link2.stl" />
      </geometry>
      <material name="link_2_mat">
        <color rgba="0.85882745 0.84706275 0.80784706 1.00000000"/>
      </material>
    </visual>
    <collision>
      <origin xyz="0 0 0" rpy="0 0 0" />
      <geometry>
        <mesh filename="meshes/lm3/collision/link2.stl" />
      </geometry>
    </collision>
    <inertial>
      <origin xyz="-0.134 0 0.094" rpy="0 0 0" />
      <mass value="1.972" />
      <inertia ixx="0.0017129" ixy="0" ixz="0.0000738" iyy="0.0336122" iyz="0" izz="0.033848" />
    </inertial>
  </link>

  <link name="link_3">
    <visual>
      <origin xyz="0 0 0" rpy="0 0 0" />
      <geometry>
        <mesh filename="meshes/lm3/visual/link3.stl" />
      </geometry>
      <material name="link_3_mat">
        <color rgba="0.85882745 0.84706275 0.80784706 1.00000000"/>
      </material>
    </visual>
    <collision>
      <origin xyz="0 0 0" rpy="0 0 0" />
      <geometry>
        <mesh filename="meshes/lm3/collision/link3.stl" />
      </geometry>
    </collision>
    <inertial>
      <origin xyz="-0.102 0 0.019" rpy="0 0 0" />
      <mass value="1.668" />
      <inertia ixx="0.0017093" ixy="0" ixz="-0.0027506" iyy="0.022564" iyz="0" izz="0.0223839" />
    </inertial>
  </link>

  <link name="link_4">
    <visual>
      <origin xyz="0 0 0" rpy="0 0 0" />
      <geometry>
        <mesh filename="meshes/lm3/visual/link4.stl" />
      </geometry>
      <material name="link_4_mat">
        <color rgba="0.85882745 0.84706275 0.80784706 1.00000000"/>
      </material>
    </visual>
    <collision>
      <origin xyz="0 0 0" rpy="0 0 0" />
      <geometry>
        <mesh filename="meshes/lm3/collision/link4.stl" />
      </geometry>
    </collision>
    <inertial>
      <origin xyz="0 0.011 -0.039" rpy="0 0 0" />
      <mass value="0.969" />
      <inertia ixx="0.0018744" ixy="0" ixz="0" iyy="0.001781" iyz="-0.0004004" izz="0.0007962" />
    </inertial>
  </link>

  <link name="link_5">
    <visual>
      <origin xyz="0 0 0" rpy="0 0 0" />
      <geometry>
        <mesh filename="meshes/lm3/visual/link5.stl" />
      </geometry>
      <material name="link_5_mat">
        <color rgba="0.85882745 0.84706275 0.80784706 1.00000000"/>
      </material>
    </visual>
    <collision>
      <origin xyz="0 0 0" rpy="0 0 0" />
      <geometry>
        <mesh filename="meshes/lm3/collision/link5.stl" />
      </geometry>
    </collision>
    <inertial>
      <origin xyz="0 -0.011 -0.039" rpy="0 0 0" />
      <mass value="0.969" />
      <inertia ixx="0.0018744" ixy="0" ixz="0" iyy="0.001781" iyz="0.0004004" izz="0.0007962" />
    </inertial>
  </link>

  <link name="link_6">
    <visual>
      <origin xyz="0 0 0" rpy="0 0 0" />
      <geometry>
        <mesh filename="meshes/lm3/visual/link6.stl" />
      </geometry>
      <material name="link_6_mat">
        <color rgba="0.85882745 0.84706275 0.80784706 1.00000000"/>
      </material>
    </visual>
    <collision>
      <origin xyz="0 0 0" rpy="0 0 0" />
      <geometry>
        <mesh filename="meshes/lm3/collision/link6.stl" />
      </geometry>
    </collision>
    <inertial>
      <origin xyz="0 0 -0.049" rpy="0 0 0" />
      <mass value="0.584" />
      <inertia ixx="0.0005043" ixy="0" ixz="0" iyy="0.0005156" iyz="0" izz="0.0004119" />
    </inertial>
  </link>

  <link name="base">
  </link>

  <link name="tool0">
  </link>

  <joint name="joint_1" type="revolute">
    <parent link="base_link" />
    <child link="link_1" />
    <origin xyz="0 0 0.21583" rpy="0 0 0" />
    <axis xyz="0 0 1" />
    <limit lower="-6.28" upper="6.28" effort="100" velocity="3.14" />
  </joint>

  <joint name="joint_2" type="revolute">
    <parent link="link_1" />
    <child link="link_2" />
    <origin xyz="0 0 0" rpy="1.5707963 0 0" />
    <axis xyz="0 0 1" />
    <limit lower="-6.28" upper="6.28" effort="100" velocity="3.14" />
  </joint>

  <joint name="joint_3" type="revolute">
    <parent link="link_2" />
    <child link="link_3" />
    <origin xyz="-0.28 0 0" rpy="0 0 0" />
    <axis xyz="0 0 1" />
    <limit lower="-6.28" upper="6.28" effort="100" velocity="3.14" />
  </joint>

  <joint name="joint_4" type="revolute">
    <parent link="link_3" />
    <child link="link_4" />
    <origin xyz="-0.26 0 0.12063" rpy="0 0 0" />
    <axis xyz="0 0 1" />
    <limit lower="-6.28" upper="6.28" effort="100" velocity="3.14" />
  </joint>

  <joint name="joint_5" type="revolute">
    <parent link="link_4" />
    <child link="link_5" />
    <origin xyz="0 -0.09833 0" rpy="1.5707963 0 0" />
    <axis xyz="0 0 1" />
    <limit lower="-6.28" upper="6.28" effort="5.5" velocity="3.14" />
  </joint>

  <joint name="joint_6" type="revolute">
    <parent link="link_5" />
    <child link="link_6" />
    <origin xyz="0 0.08343 0" rpy="-1.5707963 0 0" />
    <axis xyz="0 0 1" />
    <limit lower="-6.28" upper="6.28" effort="4.6" velocity="3.14" />
  </joint>

  <joint name="joint_6-tool0" type="fixed">
    <parent link="link_6" />
    <child link="tool0" />
    <origin xyz="0 0 0" rpy="0 0 0" />
  </joint>

  <joint name="base_link-base" type="fixed">
    <parent link="base_link" />
    <child link="base" />
    <origin xyz="0 0 0" rpy="0 0 0" />
  </joint>

  <joint name="fixed" type="fixed">
    <parent link="world" />
    <child link="base_link" />
    <origin xyz="0 0 0" rpy="0 0 0" />
  </joint>

</robot>